Workbook

Sheet Instructions
A1: Readiness Scorecard (Kitara example): Enterprise Data Readiness for AI
A3: Score your organisation on five dimensions. Each dimension has up to six evidence rows.
A4: 1. Write one piece of evidence per row (a document, a report, a system screen) and name the person who could verify it.
A5: 2. Give the item a score from 1 to 5. The Levels guide sheet describes each level.
A6: 3. Set Evidence seen to Y only when someone outside your team has seen the evidence. Leave it N when the score rests on what someone told you.
A7: 4. Read the summary under the table. The evidence-adjusted mean counts only the rows with Evidence seen = Y.
A8: 5. Set a target level for each dimension. The gap shows how far each dimension has to move.
A9: Do not score a row without evidence. A blank row is better than a guess.
A11: Cells with a light cream tint are for your input. All other cells are formulas or fixed text.

Sheet Scorecard
A1: Readiness Scorecard (Kitara example)
A2: Organisation: | B2: Kitara Group (fictional) | D2: Date scored: | E2: 2026-10-29
A4: Dimension | B4: Evidence item | C4: What exists (the evidence) | D4: Who could verify it | E4: Score (1 to 5) | F4: Evidence seen (Y/N) | G4: Level name
A5: Use cases and sponsorship | B5: Named executive sponsor | C5: The chief executive says in interviews that AI is a board priority. No written mandate or budget owner. | D5: Company Secretary (board papers) | E5: 4 | F5: N | G5: =IF(E5="","",INDEX('Levels guide'!$B$2:$B$6,E5))
A6: Use cases and sponsorship | B6: List of candidate use cases | C6: Eleven ideas were listed on one workshop slide in May 2026. No owners or data needs. | D6: Head of IT | E6: 4 | F6: N | G6: =IF(E6="","",INDEX('Levels guide'!$B$2:$B$6,E6))
A7: Use cases and sponsorship | B7: Business case for the first use | C7: A one-page case for document search over policies, with a pilot budget approved by IT Steering on 9 June 2026. | D7: Chair of IT Steering Committee | E7: 3 | F7: Y | G7: =IF(E7="","",INDEX('Levels guide'!$B$2:$B$6,E7))
A8: Use cases and sponsorship | B8: Funded budget | C8: UGX 38,000,000 pilot budget approved. No multi-year budget. | D8: Chief Finance Officer | E8: 2 | F8: Y | G8: =IF(E8="","",INDEX('Levels guide'!$B$2:$B$6,E8))
A9: Use cases and sponsorship | B9: Success measures | C9: No baseline for time to find an answer or days to settle a claim. Only the claims ratio is reported. | D9: Head of Claims | E9: 2 | F9: Y | G9: =IF(E9="","",INDEX('Levels guide'!$B$2:$B$6,E9))
A10: Use cases and sponsorship | G10: =IF(E10="","",INDEX('Levels guide'!$B$2:$B$6,E10))
A11: Data: inventory, quality and metadata | B11: Source inventory | C11: A spreadsheet of 14 sources compiled for IT Steering. Four have no owner, five have no sensitivity class, none is in a catalogue. | D11: IT Steering Committee secretary | E11: 2 | F11: Y | G11: =IF(E11="","",INDEX('Levels guide'!$B$2:$B$6,E11))
A12: Data: inventory, quality and metadata | B12: Quality monitoring | C12: Finance says customer data is checked every month. No rule list or result log was provided. | D12: Head of Retail Banking Operations | E12: 3 | F12: N | G12: =IF(E12="","",INDEX('Levels guide'!$B$2:$B$6,E12))
A13: Data: inventory, quality and metadata | B13: Metadata and catalogue | C13: No catalogue. Column meanings are in two PDF files from the core banking vendor. | D13: Core Banking Data Analyst | E13: 1 | F13: Y | G13: =IF(E13="","",INDEX('Levels guide'!$B$2:$B$6,E13))
A14: Data: inventory, quality and metadata | B14: Document version control | C14: The shared drive holds about 14,000 files. Three editions of the staff handbook sit in one folder. | D14: Head of Legal and Compliance | E14: 1 | F14: Y | G14: =IF(E14="","",INDEX('Levels guide'!$B$2:$B$6,E14))
A15: Data: inventory, quality and metadata | B15: Customer master data | C15: The head of retail says one customer ID is used across systems. The Risk Committee noted two regulatory returns corrected because of duplicate customer records. | D15: Head of Risk | E15: 3 | F15: N | G15: =IF(E15="","",INDEX('Levels guide'!$B$2:$B$6,E15))
A16: Data: inventory, quality and metadata | G16: =IF(E16="","",INDEX('Levels guide'!$B$2:$B$6,E16))
A17: Platform and pipelines | B17: Core data extract | C17: Nightly extract from core banking to a reporting database. Run log kept for 90 days. | D17: IT operations lead | E17: 3 | F17: Y | G17: =IF(E17="","",INDEX('Levels guide'!$B$2:$B$6,E17))
A18: Platform and pipelines | B18: Backup and recovery | C18: Business Continuity Plan sets four hours for core banking. A recovery test is held each March. | D18: Head of Risk | E18: 3 | F18: Y | G18: =IF(E18="","",INDEX('Levels guide'!$B$2:$B$6,E18))
A19: Platform and pipelines | B19: Analytics platform | C19: IT reports a reporting database and a data lake 'in progress'. No access was shown to the assessor. | D19: Head of IT | E19: 3 | F19: N | G19: =IF(E19="","",INDEX('Levels guide'!$B$2:$B$6,E19))
A20: Platform and pipelines | B20: Pipeline orchestration | C20: Scheduled jobs on two servers using cron. No dependency, retry or alert logic. | D20: IT operations lead | E20: 2 | F20: Y | G20: =IF(E20="","",INDEX('Levels guide'!$B$2:$B$6,E20))
A21: Platform and pipelines | B21: Monitoring of data freshness | C21: No freshness or volume alerts. A six-hour gap in the mobile money log was found by hand. | D21: IT operations lead | E21: 2 | F21: Y | G21: =IF(E21="","",INDEX('Levels guide'!$B$2:$B$6,E21))
A22: Platform and pipelines | B22: Environment for AI work | C22: An internal AI sandbox pilot is approved. It is not yet built. | D22: Head of IT | E22: 2 | F22: Y | G22: =IF(E22="","",INDEX('Levels guide'!$B$2:$B$6,E22))
A23: Protection and law | B23: Registration and data protection officer | C23: Kitara says it is registered with the data protection regulator and has named an officer. The certificate was not seen. | D23: Head of Legal and Compliance | E23: 4 | F23: N | G23: =IF(E23="","",INDEX('Levels guide'!$B$2:$B$6,E23))
A24: Protection and law | B24: Breach procedure | C24: The Information Security Policy sets one hour to report internally and 72 hours to report to the regulator. | D24: Head of IT Security | E24: 3 | F24: Y | G24: =IF(E24="","",INDEX('Levels guide'!$B$2:$B$6,E24))
A25: Protection and law | B25: Classification scheme | C25: The Data Classification Standard has four classes. Two sources in the inventory carry the wrong class. | D25: Head of Legal and Compliance | E25: 3 | F25: Y | G25: =IF(E25="","",INDEX('Levels guide'!$B$2:$B$6,E25))
A26: Protection and law | B26: Retention schedule | C26: A retention schedule exists. Legal says it is applied. No destruction list was provided. | D26: Head of Legal and Compliance | E26: 3 | F26: N | G26: =IF(E26="","",INDEX('Levels guide'!$B$2:$B$6,E26))
A27: Protection and law | B27: Cross-border data flows | C27: Kitara Kenya data is processed in Kampala. No transfer assessment is on file. | D27: Head of Legal and Compliance | E27: 2 | F27: Y | G27: =IF(E27="","",INDEX('Levels guide'!$B$2:$B$6,E27))
A28: Protection and law | G28: =IF(E28="","",INDEX('Levels guide'!$B$2:$B$6,E28))
A29: People and governance | B29: Named data owners | C29: Ten of 14 sources have an owner. Two owners are recorded as IT while a business unit also claims the source. | D29: Head of IT | E29: 1 | F29: Y | G29: =IF(E29="","",INDEX('Levels guide'!$B$2:$B$6,E29))
A30: People and governance | B30: Data governance forum | C30: The heads say a data council meets informally. There are no minutes. | D30: Company Secretary | E30: 2 | F30: N | G30: =IF(E30="","",INDEX('Levels guide'!$B$2:$B$6,E30))
A31: People and governance | B31: Policies for data and AI | C31: Classification, retention and acceptable AI use policies exist and were published in 2024 to 2026. | D31: Head of Legal and Compliance | E31: 2 | F31: Y | G31: =IF(E31="","",INDEX('Levels guide'!$B$2:$B$6,E31))
A32: People and governance | B32: Data and AI skills | C32: Two analysts in Finance and Risk. No data engineer. No AI training for staff. | D32: Head of Human Resources | E32: 1 | F32: Y | G32: =IF(E32="","",INDEX('Levels guide'!$B$2:$B$6,E32))
A33: People and governance | G33: =IF(E33="","",INDEX('Levels guide'!$B$2:$B$6,E33))
A34: People and governance | G34: =IF(E34="","",INDEX('Levels guide'!$B$2:$B$6,E34))
A36: Summary
A37: Dimension | B37: Items scored | C37: Mean score | D37: Evidence-adjusted mean | E37: Target level (1 to 5) | F37: Gap to target (adjusted) | G37: Weakest?
A38: Use cases and sponsorship | B38: =COUNTIFS($A$5:$A$34,A38,$E$5:$E$34,">0") | C38: =IFERROR(AVERAGEIFS($E$5:$E$34,$A$5:$A$34,A38),"") | D38: =IFERROR(AVERAGEIFS($E$5:$E$34,$A$5:$A$34,A38,$F$5:$F$34,"Y"),"") | E38: 3 | F38: =IF(D38="","",MAX(0,E38-D38)) | G38: =IF(AND(D38<>"",D38=MIN($D$38:$D$42)),"Weakest","")
A39: Data: inventory, quality and metadata | B39: =COUNTIFS($A$5:$A$34,A39,$E$5:$E$34,">0") | C39: =IFERROR(AVERAGEIFS($E$5:$E$34,$A$5:$A$34,A39),"") | D39: =IFERROR(AVERAGEIFS($E$5:$E$34,$A$5:$A$34,A39,$F$5:$F$34,"Y"),"") | E39: 3 | F39: =IF(D39="","",MAX(0,E39-D39)) | G39: =IF(AND(D39<>"",D39=MIN($D$38:$D$42)),"Weakest","")
A40: Platform and pipelines | B40: =COUNTIFS($A$5:$A$34,A40,$E$5:$E$34,">0") | C40: =IFERROR(AVERAGEIFS($E$5:$E$34,$A$5:$A$34,A40),"") | D40: =IFERROR(AVERAGEIFS($E$5:$E$34,$A$5:$A$34,A40,$F$5:$F$34,"Y"),"") | E40: 3 | F40: =IF(D40="","",MAX(0,E40-D40)) | G40: =IF(AND(D40<>"",D40=MIN($D$38:$D$42)),"Weakest","")
A41: Protection and law | B41: =COUNTIFS($A$5:$A$34,A41,$E$5:$E$34,">0") | C41: =IFERROR(AVERAGEIFS($E$5:$E$34,$A$5:$A$34,A41),"") | D41: =IFERROR(AVERAGEIFS($E$5:$E$34,$A$5:$A$34,A41,$F$5:$F$34,"Y"),"") | E41: 3 | F41: =IF(D41="","",MAX(0,E41-D41)) | G41: =IF(AND(D41<>"",D41=MIN($D$38:$D$42)),"Weakest","")
A42: People and governance | B42: =COUNTIFS($A$5:$A$34,A42,$E$5:$E$34,">0") | C42: =IFERROR(AVERAGEIFS($E$5:$E$34,$A$5:$A$34,A42),"") | D42: =IFERROR(AVERAGEIFS($E$5:$E$34,$A$5:$A$34,A42,$F$5:$F$34,"Y"),"") | E42: 3 | F42: =IF(D42="","",MAX(0,E42-D42)) | G42: =IF(AND(D42<>"",D42=MIN($D$38:$D$42)),"Weakest","")
...

Sheet Levels guide
A1: Level | B1: Name | C1: What it looks like | D1: Evidence you would expect
A2: 1 | B2: Ad hoc | C2: Done by individuals when needed. Nothing written down. Different answers from different people. | D2: A person's account only. No documents.
A3: 2 | B3: Developing | C3: Some written practice in some places. Not applied across the organisation. | D3: A document or list that covers part of the organisation, with gaps you can name.
A4: 3 | B4: Defined | C4: A standard exists and most units know it. Owners are named. Gaps are known. | D4: An approved policy, a complete list, a named owner, one report that uses them.
A5: 4 | B5: Managed | C5: The standard is measured. Someone reviews the numbers and acts on them. | D5: Monthly figures, a log of actions, minutes showing decisions.
A6: 5 | B6: Optimised | C6: The measures drive regular improvement. Changes are tested before they are rolled out. | D6: A year of trend data and a record of improvements made from it.
